<?xml version="1.0"?>
<robot name="two_link_planar">
  <link name="base_link"/>
  <link name="link1"/>
  <link name="link2"/>
  <link name="ee_link"/>
  <joint name="joint1" type="revolute">
    <parent link="base_link"/>
    <child link="link1"/>
    <origin xyz="0 0 0" rpy="0 0 0"/>
    <axis xyz="0 0 1"/>
    <limit lower="-3.14159" upper="3.14159" effort="20" velocity="3"/>
  </joint>
  <joint name="joint2" type="revolute">
    <parent link="link1"/>
    <child link="link2"/>
    <origin xyz="1 0 0" rpy="0 0 0"/>
    <axis xyz="0 0 1"/>
    <limit lower="-3.14159" upper="3.14159" effort="20" velocity="3"/>
  </joint>
  <joint name="ee_fixed" type="fixed">
    <parent link="link2"/>
    <child link="ee_link"/>
    <origin xyz="1 0 0" rpy="0 0 0"/>
  </joint>
</robot>
